# Generated by Django 3.2 on 2021-06-24 19:58

from django.db import migrations, models


class Migration(migrations.Migration):

    dependencies = [
        ('conference', '0008_auto_20210618_0312'),
    ]

    operations = [
        migrations.CreateModel(
            name='ReceivedException',
            fields=[
                ('id', models.BigAutoField(auto_created=True, primary_key=True, serialize=False, verbose_name='ID')),
                ('function_name', models.CharField(blank=True, default='unknown', max_length=10000)),
                ('exception_args', models.CharField(blank=True, default='unknown', max_length=10000)),
                ('exception_message', models.CharField(blank=True, default='unknown', max_length=10000)),
                ('general_info', models.CharField(blank=True, default='unknown', max_length=10000)),
                ('current_user_info', models.CharField(blank=True, default='unknown', max_length=10000)),
            ],
        ),
    ]
